Workbook
Name StartBank: Settings!$B$3
Name StartDate: Settings!$B$4
Name UnitPct: Settings!$B$5
Name KellySingle: Settings!$B$6
Name KellyBuilder: Settings!$B$7
Name MinEdgeSingle: Settings!$B$8
Name MinEdgePlayer: Settings!$B$9
Name MinEdgeBuilder: Settings!$B$10
Name CapSingle: Settings!$B$11
Name CapBuilder: Settings!$B$12
Name CapDay: Settings!$B$13
Name StopLoss: Settings!$B$14
Name CurrentBank: Settings!$B$16
Name Unit: Settings!$B$17

Sheet Summary
A1: Betting record
A3: Bets placed | B3: =COUNTA(Bets!$L$2:$L$2001)
A4: Settled | B4: =COUNTIFS(Bets!$M$2:$M$2001,"<>Pending",Bets!$M$2:$M$2001,"<>",Bets!$L$2:$L$2001,"<>")
A5: Pending | B5: =COUNTIFS(Bets!$M$2:$M$2001,"Pending")
A6: Total staked (settled) | B6: =SUMIFS(Bets!$L$2:$L$2001,Bets!$M$2:$M$2001,"<>Pending",Bets!$M$2:$M$2001,"<>")
A7: Total returned | B7: =SUM(Bets!$O$2:$O$2001)
A8: Profit / loss | B8: =SUM(Bets!$P$2:$P$2001)
A9: ROI (profit ÷ staked) | B9: =IF(SUMIFS(Bets!$L$2:$L$2001,Bets!$M$2:$M$2001,"<>Pending",Bets!$M$2:$M$2001,"<>")=0,"",SUM(Bets!$P$2:$P$2001)/SUMIFS(Bets!$L$2:$L$2001,Bets!$M$2:$M$2001,"<>Pending",Bets!$M$2:$M$2001,"<>"))
A10: Strike rate (won ÷ won+lost) | B10: =IFERROR(COUNTIFS(Bets!$M$2:$M$2001,"Won")/(COUNTIFS(Bets!$M$2:$M$2001,"Won")+COUNTIFS(Bets!$M$2:$M$2001,"Lost")),"")
A11: Average odds (settled) | B11: =IFERROR(SUMPRODUCT((Bets!$M$2:$M$2001="Won")+(Bets!$M$2:$M$2001="Lost"),Bets!$G$2:$G$2001)/(COUNTIFS(Bets!$M$2:$M$2001,"Won")+COUNTIFS(Bets!$M$2:$M$2001,"Lost")),"")
A12: Expected profit (model) | B12: =SUMIFS(Bets!$S$2:$S$2001,Bets!$M$2:$M$2001,"<>Pending",Bets!$M$2:$M$2001,"<>")
A13: Actual minus expected | B13: =B8-B12
A14: Average closing-line value | B14: =IFERROR(AVERAGE(Bets!$R$2:$R$2001),"")
A15: Bets that beat the closing odds | B15: =IFERROR(COUNTIF(Bets!$R$2:$R$2001,">0")/COUNT(Bets!$R$2:$R$2001),"")
A16: Current bank | B16: =CurrentBank
A17: Bank change since start | B17: =IF(StartBank=0,"",CurrentBank/StartBank-1)
A19: ROI is your real return per £ staked. Closing-line value (CLV) shows whether you are getting better odds than the final market price; over hundreds of bets it is the best early sign of a genuine edge.
A21: By bet type | B21: Bets | C21: Staked | D21: Profit | E21: ROI | F21: Won | G21: Strike rate
A22: Single | B22: =COUNTIFS(Bets!$D$2:$D$2001,$A22,Bets!$M$2:$M$2001,"<>Pending",Bets!$M$2:$M$2001,"<>") | C22: =SUMIFS(Bets!$L$2:$L$2001,Bets!$D$2:$D$2001,$A22,Bets!$M$2:$M$2001,"<>Pending",Bets!$M$2:$M$2001,"<>") | D22: =SUMIFS(Bets!$P$2:$P$2001,Bets!$D$2:$D$2001,$A22,Bets!$M$2:$M$2001,"<>Pending",Bets!$M$2:$M$2001,"<>") | E22: =IF(C22=0,"",D22/C22) | F22: =COUNTIFS(Bets!$D$2:$D$2001,$A22,Bets!$M$2:$M$2001,"Won") | G22: =IFERROR(F22/(F22+COUNTIFS(Bets!$D$2:$D$2001,$A22,Bets!$M$2:$M$2001,"Lost")),"")
A23: Player | B23: =COUNTIFS(Bets!$D$2:$D$2001,$A23,Bets!$M$2:$M$2001,"<>Pending",Bets!$M$2:$M$2001,"<>") | C23: =SUMIFS(Bets!$L$2:$L$2001,Bets!$D$2:$D$2001,$A23,Bets!$M$2:$M$2001,"<>Pending",Bets!$M$2:$M$2001,"<>") | D23: =SUMIFS(Bets!$P$2:$P$2001,Bets!$D$2:$D$2001,$A23,Bets!$M$2:$M$2001,"<>Pending",Bets!$M$2:$M$2001,"<>") | E23: =IF(C23=0,"",D23/C23) | F23: =COUNTIFS(Bets!$D$2:$D$2001,$A23,Bets!$M$2:$M$2001,"Won") | G23: =IFERROR(F23/(F23+COUNTIFS(Bets!$D$2:$D$2001,$A23,Bets!$M$2:$M$2001,"Lost")),"")
A24: Builder | B24: =COUNTIFS(Bets!$D$2:$D$2001,$A24,Bets!$M$2:$M$2001,"<>Pending",Bets!$M$2:$M$2001,"<>") | C24: =SUMIFS(Bets!$L$2:$L$2001,Bets!$D$2:$D$2001,$A24,Bets!$M$2:$M$2001,"<>Pending",Bets!$M$2:$M$2001,"<>") | D24: =SUMIFS(Bets!$P$2:$P$2001,Bets!$D$2:$D$2001,$A24,Bets!$M$2:$M$2001,"<>Pending",Bets!$M$2:$M$2001,"<>") | E24: =IF(C24=0,"",D24/C24) | F24: =COUNTIFS(Bets!$D$2:$D$2001,$A24,Bets!$M$2:$M$2001,"Won") | G24: =IFERROR(F24/(F24+COUNTIFS(Bets!$D$2:$D$2001,$A24,Bets!$M$2:$M$2001,"Lost")),"")
A26: By market | B26: Bets | C26: Staked | D26: Profit | E26: ROI | F26: Won | G26: Strike rate
A27: Result | B27: =COUNTIFS(Bets!$E$2:$E$2001,$A27,Bets!$M$2:$M$2001,"<>Pending",Bets!$M$2:$M$2001,"<>") | C27: =SUMIFS(Bets!$L$2:$L$2001,Bets!$E$2:$E$2001,$A27,Bets!$M$2:$M$2001,"<>Pending",Bets!$M$2:$M$2001,"<>") | D27: =SUMIFS(Bets!$P$2:$P$2001,Bets!$E$2:$E$2001,$A27,Bets!$M$2:$M$2001,"<>Pending",Bets!$M$2:$M$2001,"<>") | E27: =IF(C27=0,"",D27/C27) | F27: =COUNTIFS(Bets!$E$2:$E$2001,$A27,Bets!$M$2:$M$2001,"Won") | G27: =IFERROR(F27/(F27+COUNTIFS(Bets!$E$2:$E$2001,$A27,Bets!$M$2:$M$2001,"Lost")),"")
A28: Goals | B28: =COUNTIFS(Bets!$E$2:$E$2001,$A28,Bets!$M$2:$M$2001,"<>Pending",Bets!$M$2:$M$2001,"<>") | C28: =SUMIFS(Bets!$L$2:$L$2001,Bets!$E$2:$E$2001,$A28,Bets!$M$2:$M$2001,"<>Pending",Bets!$M$2:$M$2001,"<>") | D28: =SUMIFS(Bets!$P$2:$P$2001,Bets!$E$2:$E$2001,$A28,Bets!$M$2:$M$2001,"<>Pending",Bets!$M$2:$M$2001,"<>") | E28: =IF(C28=0,"",D28/C28) | F28: =COUNTIFS(Bets!$E$2:$E$2001,$A28,Bets!$M$2:$M$2001,"Won") | G28: =IFERROR(F28/(F28+COUNTIFS(Bets!$E$2:$E$2001,$A28,Bets!$M$2:$M$2001,"Lost")),"")
A29: BTTS | B29: =COUNTIFS(Bets!$E$2:$E$2001,$A29,Bets!$M$2:$M$2001,"<>Pending",Bets!$M$2:$M$2001,"<>") | C29: =SUMIFS(Bets!$L$2:$L$2001,Bets!$E$2:$E$2001,$A29,Bets!$M$2:$M$2001,"<>Pending",Bets!$M$2:$M$2001,"<>") | D29: =SUMIFS(Bets!$P$2:$P$2001,Bets!$E$2:$E$2001,$A29,Bets!$M$2:$M$2001,"<>Pending",Bets!$M$2:$M$2001,"<>") | E29: =IF(C29=0,"",D29/C29) | F29: =COUNTIFS(Bets!$E$2:$E$2001,$A29,Bets!$M$2:$M$2001,"Won") | G29: =IFERROR(F29/(F29+COUNTIFS(Bets!$E$2:$E$2001,$A29,Bets!$M$2:$M$2001,"Lost")),"")
A30: Corners | B30: =COUNTIFS(Bets!$E$2:$E$2001,$A30,Bets!$M$2:$M$2001,"<>Pending",Bets!$M$2:$M$2001,"<>") | C30: =SUMIFS(Bets!$L$2:$L$2001,Bets!$E$2:$E$2001,$A30,Bets!$M$2:$M$2001,"<>Pending",Bets!$M$2:$M$2001,"<>") | D30: =SUMIFS(Bets!$P$2:$P$2001,Bets!$E$2:$E$2001,$A30,Bets!$M$2:$M$2001,"<>Pending",Bets!$M$2:$M$2001,"<>") | E30: =IF(C30=0,"",D30/C30) | F30: =COUNTIFS(Bets!$E$2:$E$2001,$A30,Bets!$M$2:$M$2001,"Won") | G30: =IFERROR(F30/(F30+COUNTIFS(Bets!$E$2:$E$2001,$A30,Bets!$M$2:$M$2001,"Lost")),"")
A31: Cards | B31: =COUNTIFS(Bets!$E$2:$E$2001,$A31,Bets!$M$2:$M$2001,"<>Pending",Bets!$M$2:$M$2001,"<>") | C31: =SUMIFS(Bets!$L$2:$L$2001,Bets!$E$2:$E$2001,$A31,Bets!$M$2:$M$2001,"<>Pending",Bets!$M$2:$M$2001,"<>") | D31: =SUMIFS(Bets!$P$2:$P$2001,Bets!$E$2:$E$2001,$A31,Bets!$M$2:$M$2001,"<>Pending",Bets!$M$2:$M$2001,"<>") | E31: =IF(C31=0,"",D31/C31) | F31: =COUNTIFS(Bets!$E$2:$E$2001,$A31,Bets!$M$2:$M$2001,"Won") | G31: =IFERROR(F31/(F31+COUNTIFS(Bets!$E$2:$E$2001,$A31,Bets!$M$2:$M$2001,"Lost")),"")
A32: Shots | B32: =COUNTIFS(Bets!$E$2:$E$2001,$A32,Bets!$M$2:$M$2001,"<>Pending",Bets!$M$2:$M$2001,"<>") | C32: =SUMIFS(Bets!$L$2:$L$2001,Bets!$E$2:$E$2001,$A32,Bets!$M$2:$M$2001,"<>Pending",Bets!$M$2:$M$2001,"<>") | D32: =SUMIFS(Bets!$P$2:$P$2001,Bets!$E$2:$E$2001,$A32,Bets!$M$2:$M$2001,"<>Pending",Bets!$M$2:$M$2001,"<>") | E32: =IF(C32=0,"",D32/C32) | F32: =COUNTIFS(Bets!$E$2:$E$2001,$A32,Bets!$M$2:$M$2001,"Won") | G32: =IFERROR(F32/(F32+COUNTIFS(Bets!$E$2:$E$2001,$A32,Bets!$M$2:$M$2001,"Lost")),"")
A33: Player | B33: =COUNTIFS(Bets!$E$2:$E$2001,$A33,Bets!$M$2:$M$2001,"<>Pending",Bets!$M$2:$M$2001,"<>") | C33: =SUMIFS(Bets!$L$2:$L$2001,Bets!$E$2:$E$2001,$A33,Bets!$M$2:$M$2001,"<>Pending",Bets!$M$2:$M$2001,"<>") | D33: =SUMIFS(Bets!$P$2:$P$2001,Bets!$E$2:$E$2001,$A33,Bets!$M$2:$M$2001,"<>Pending",Bets!$M$2:$M$2001,"<>") | E33: =IF(C33=0,"",D33/C33) | F33: =COUNTIFS(Bets!$E$2:$E$2001,$A33,Bets!$M$2:$M$2001,"Won") | G33: =IFERROR(F33/(F33+COUNTIFS(Bets!$E$2:$E$2001,$A33,Bets!$M$2:$M$2001,"Lost")),"")
A34: Builder | B34: =COUNTIFS(Bets!$E$2:$E$2001,$A34,Bets!$M$2:$M$2001,"<>Pending",Bets!$M$2:$M$2001,"<>") | C34: =SUMIFS(Bets!$L$2:$L$2001,Bets!$E$2:$E$2001,$A34,Bets!$M$2:$M$2001,"<>Pending",Bets!$M$2:$M$2001,"<>") | D34: =SUMIFS(Bets!$P$2:$P$2001,Bets!$E$2:$E$2001,$A34,Bets!$M$2:$M$2001,"<>Pending",Bets!$M$2:$M$2001,"<>") | E34: =IF(C34=0,"",D34/C34) | F34: =COUNTIFS(Bets!$E$2:$E$2001,$A34,Bets!$M$2:$M$2001,"Won") | G34: =IFERROR(F34/(F34+COUNTIFS(Bets!$E$2:$E$2001,$A34,Bets!$M$2:$M$2001,"Lost")),"")
A35: Other | B35: =COUNTIFS(Bets!$E$2:$E$2001,$A35,Bets!$M$2:$M$2001,"<>Pending",Bets!$M$2:$M$2001,"<>") | C35: =SUMIFS(Bets!$L$2:$L$2001,Bets!$E$2:$E$2001,$A35,Bets!$M$2:$M$2001,"<>Pending",Bets!$M$2:$M$2001,"<>") | D35: =SUMIFS(Bets!$P$2:$P$2001,Bets!$E$2:$E$2001,$A35,Bets!$M$2:$M$2001,"<>Pending",Bets!$M$2:$M$2001,"<>") | E35: =IF(C35=0,"",D35/C35) | F35: =COUNTIFS(Bets!$E$2:$E$2001,$A35,Bets!$M$2:$M$2001,"Won") | G35: =IFERROR(F35/(F35+COUNTIFS(Bets!$E$2:$E$2001,$A35,Bets!$M$2:$M$2001,"Lost")),"")
A37: By month | B37: Bets | C37: Staked | D37: Profit | E37: ROI | F37: Bank at month end
A38: 46296 | B38: =COUNTIFS(Bets!$A$2:$A$2001,">="&$A38,Bets!$A$2:$A$2001,"<"&EDATE($A38,1),Bets!$M$2:$M$2001,"<>Pending",Bets!$M$2:$M$2001,"<>") | C38: =SUMIFS(Bets!$L$2:$L$2001,Bets!$A$2:$A$2001,">="&$A38,Bets!$A$2:$A$2001,"<"&EDATE($A38,1),Bets!$M$2:$M$2001,"<>Pending",Bets!$M$2:$M$2001,"<>") | D38: =SUMIFS(Bets!$P$2:$P$2001,Bets!$A$2:$A$2001,">="&$A38,Bets!$A$2:$A$2001,"<"&EDATE($A38,1),Bets!$M$2:$M$2001,"<>Pending",Bets!$M$2:$M$2001,"<>") | E38: =IF(C38=0,"",D38/C38) | F38: =StartBank+SUMIFS(Bets!$P$2:$P$2001,Bets!$A$2:$A$2001,"<"&EDATE($A38,1))
A39: 46327 | B39: =COUNTIFS(Bets!$A$2:$A$2001,">="&$A39,Bets!$A$2:$A$2001,"<"&EDATE($A39,1),Bets!$M$2:$M$2001,"<>Pending",Bets!$M$2:$M$2001,"<>") | C39: =SUMIFS(Bets!$L$2:$L$2001,Bets!$A$2:$A$2001,">="&$A39,Bets!$A$2:$A$2001,"<"&EDATE($A39,1),Bets!$M$2:$M$2001,"<>Pending",Bets!$M$2:$M$2001,"<>") | D39: =SUMIFS(Bets!$P$2:$P$2001,Bets!$A$2:$A$2001,">="&$A39,Bets!$A$2:$A$2001,"<"&EDATE($A39,1),Bets!$M$2:$M$2001,"<>Pending",Bets!$M$2:$M$2001,"<>") | E39: =IF(C39=0,"",D39/C39) | F39: =StartBank+SUMIFS(Bets!$P$2:$P$2001,Bets!$A$2:$A$2001,"<"&EDATE($A39,1))
A40: 46357 | B40: =COUNTIFS(Bets!$A$2:$A$2001,">="&$A40,Bets!$A$2:$A$2001,"<"&EDATE($A40,1),Bets!$M$2:$M$2001,"<>Pending",Bets!$M$2:$M$2001,"<>") | C40: =SUMIFS(Bets!$L$2:$L$2001,Bets!$A$2:$A$2001,">="&$A40,Bets!$A$2:$A$2001,"<"&EDATE($A40,1),Bets!$M$2:$M$2001,"<>Pending",Bets!$M$2:$M$2001,"<>") | D40: =SUMIFS(Bets!$P$2:$P$2001,Bets!$A$2:$A$2001,">="&$A40,Bets!$A$2:$A$2001,"<"&EDATE($A40,1),Bets!$M$2:$M$2001,"<>Pending",Bets!$M$2:$M$2001,"<>") | E40: =IF(C40=0,"",D40/C40) | F40: =StartBank+SUMIFS(Bets!$P$2:$P$2001,Bets!$A$2:$A$2001,"<"&EDATE($A40,1))
A41: 46388 | B41: =COUNTIFS(Bets!$A$2:$A$2001,">="&$A41,Bets!$A$2:$A$2001,"<"&EDATE($A41,1),Bets!$M$2:$M$2001,"<>Pending",Bets!$M$2:$M$2001,"<>") | C41: =SUMIFS(Bets!$L$2:$L$2001,Bets!$A$2:$A$2001,">="&$A41,Bets!$A$2:$A$2001,"<"&EDATE($A41,1),Bets!$M$2:$M$2001,"<>Pending",Bets!$M$2:$M$2001,"<>") | D41: =SUMIFS(Bets!$P$2:$P$2001,Bets!$A$2:$A$2001,">="&$A41,Bets!$A$2:$A$2001,"<"&EDATE($A41,1),Bets!$M$2:$M$2001,"<>Pending",Bets!$M$2:$M$2001,"<>") | E41: =IF(C41=0,"",D41/C41) | F41: =StartBank+SUMIFS(Bets!$P$2:$P$2001,Bets!$A$2:$A$2001,"<"&EDATE($A41,1))
A42: 46419 | B42: =COUNTIFS(Bets!$A$2:$A$2001,">="&$A42,Bets!$A$2:$A$2001,"<"&EDATE($A42,1),Bets!$M$2:$M$2001,"<>Pending",Bets!$M$2:$M$2001,"<>") | C42: =SUMIFS(Bets!$L$2:$L$2001,Bets!$A$2:$A$2001,">="&$A42,Bets!$A$2:$A$2001,"<"&EDATE($A42,1),Bets!$M$2:$M$2001,"<>Pending",Bets!$M$2:$M$2001,"<>") | D42: =SUMIFS(Bets!$P$2:$P$2001,Bets!$A$2:$A$2001,">="&$A42,Bets!$A$2:$A$2001,"<"&EDATE($A42,1),Bets!$M$2:$M$2001,"<>Pending",Bets!$M$2:$M$2001,"<>") | E42: =IF(C42=0,"",D42/C42) | F42: =StartBank+SUMIFS(Bets!$P$2:$P$2001,Bets!$A$2:$A$2001,"<"&EDATE($A42,1))
A43: 46447 | B43: =COUNTIFS(Bets!$A$2:$A$2001,">="&$A43,Bets!$A$2:$A$2001,"<"&EDATE($A43,1),Bets!$M$2:$M$2001,"<>Pending",Bets!$M$2:$M$2001,"<>") | C43: =SUMIFS(Bets!$L$2:$L$2001,Bets!$A$2:$A$2001,">="&$A43,Bets!$A$2:$A$2001,"<"&EDATE($A43,1),Bets!$M$2:$M$2001,"<>Pending",Bets!$M$2:$M$2001,"<>") | D43: =SUMIFS(Bets!$P$2:$P$2001,Bets!$A$2:$A$2001,">="&$A43,Bets!$A$2:$A$2001,"<"&EDATE($A43,1),Bets!$M$2:$M$2001,"<>Pending",Bets!$M$2:$M$2001,"<>") | E43: =IF(C43=0,"",D43/C43) | F43: =StartBank+SUMIFS(Bets!$P$2:$P$2001,Bets!$A$2:$A$2001,"<"&EDATE($A43,1))
A44: 46478 | B44: =COUNTIFS(Bets!$A$2:$A$2001,">="&$A44,Bets!$A$2:$A$2001,"<"&EDATE($A44,1),Bets!$M$2:$M$2001,"<>Pending",Bets!$M$2:$M$2001,"<>") | C44: =SUMIFS(Bets!$L$2:$L$2001,Bets!$A$2:$A$2001,">="&$A44,Bets!$A$2:$A$2001,"<"&EDATE($A44,1),Bets!$M$2:$M$2001,"<>Pending",Bets!$M$2:$M$2001,"<>") | D44: =SUMIFS(Bets!$P$2:$P$2001,Bets!$A$2:$A$2001,">="&$A44,Bets!$A$2:$A$2001,"<"&EDATE($A44,1),Bets!$M$2:$M$2001,"<>Pending",Bets!$M$2:$M$2001,"<>") | E44: =IF(C44=0,"",D44/C44) | F44: =StartBank+SUMIFS(Bets!$P$2:$P$2001,Bets!$A$2:$A$2001,"<"&EDATE($A44,1))
A45: 46508 | B45: =COUNTIFS(Bets!$A$2:$A$2001,">="&$A45,Bets!$A$2:$A$2001,"<"&EDATE($A45,1),Bets!$M$2:$M$2001,"<>Pending",Bets!$M$2:$M$2001,"<>") | C45: =SUMIFS(Bets!$L$2:$L$2001,Bets!$A$2:$A$2001,">="&$A45,Bets!$A$2:$A$2001,"<"&EDATE($A45,1),Bets!$M$2:$M$2001,"<>Pending",Bets!$M$2:$M$2001,"<>") | D45: =SUMIFS(Bets!$P$2:$P$2001,Bets!$A$2:$A$2001,">="&$A45,Bets!$A$2:$A$2001,"<"&EDATE($A45,1),Bets!$M$2:$M$2001,"<>Pending",Bets!$M$2:$M$2001,"<>") | E45: =IF(C45=0,"",D45/C45) | F45: =StartBank+SUMIFS(Bets!$P$2:$P$2001,Bets!$A$2:$A$2001,"<"&EDATE($A45,1))
...

Sheet Settings
A1: Staking settings
A3: Starting bank (£) | B3: 500 | C3: Money set aside purely for betting, that you can afford to lose.
A4: Start date | B4: 46304
A5: Unit size (% of bank) | B5: 0.01 | C5: 1 unit = 1% of the bank. Re-set monthly to 1% of the current bank.
A6: Kelly fraction: singles | B6: 0.25 | C6: Quarter Kelly on result, goals, corners and cards singles.
A7: Kelly fraction: player bets and builders | B7: 0.125 | C7: Eighth Kelly: these probabilities are less certain.
A8: Minimum edge: singles | B8: 0.03 | C8: Result, goals, corners, cards singles. Skip anything with a smaller edge.
A9: Minimum edge: player singles | B9: 0.05 | C9: Scorer, shots, cards for one player.
A10: Minimum edge: builders | B10: 0.08 | C10: Builders need a bigger cushion for model error.
A11: Max stake per single (units) | B11: 2
A12: Max stake per builder (units) | B12: 1
A13: Max stakes per match day (units) | B13: 5 | C13: Total across all bets that day.
A14: Stop and review if bank falls by | B14: 0.4 | C14: Pause and check the model's record before betting on.
A16: Current bank | B16: =StartBank+SUM(Bets!$P$2:$P$2001)
A17: Current unit (£) | B17: =ROUND(CurrentBank*UnitPct,2)
A19: Yellow cells are yours to change. Everything else is worked out for you.

Sheet Bets
A1: Date | B1: Match | C1: Bookmaker | D1: Type | E1: Market | F1: Selection / legs | G1: Odds | H1: Model chance | I1: Fair odds | J1: Edge | K1: Suggested stake | L1: Stake | M1: Result | N1: Cash-out return | O1: Return | P1: Profit | Q1: Closing odds | R1: CLV | S1: Expected profit | T1: Bank after | U1: Notes
I2: =IF(OR(H2="",H2=0),"",1/H2) | J2: =IF(OR(G2="",H2=""),"",H2*G2-1) | K2: =IF(OR(G2="",H2="",G2<=1),"",IF(J2<IF(D2="Builder",MinEdgeBuilder,IF(D2="Player",MinEdgePlayer,MinEdgeSingle)),0,ROUND(MIN(IF(D2="Single",KellySingle,KellyBuilder)*(StartBank+SUM(P$1:P1))*J2/(G2-1),IF(D2="Builder",CapBuilder,CapSingle)*Unit),2))) | O2: =IF(L2="","",IF(M2="Won",L2*G2,IF(M2="Void",L2,IF(M2="Cash out",N(N2),IF(M2="Lost",0,""))))) | P2: =IF(OR(L2="",M2="",M2="Pending"),"",O2-L2) | R2: =IF(OR(G2="",Q2=""),"",G2/Q2-1) | S2: =IF(OR(L2="",J2=""),"",L2*J2) | T2: =IF(P2="","",StartBank+SUM(P$2:P2))
I3: =IF(OR(H3="",H3=0),"",1/H3) | J3: =IF(OR(G3="",H3=""),"",H3*G3-1) | K3: =IF(OR(G3="",H3="",G3<=1),"",IF(J3<IF(D3="Builder",MinEdgeBuilder,IF(D3="Player",MinEdgePlayer,MinEdgeSingle)),0,ROUND(MIN(IF(D3="Single",KellySingle,KellyBuilder)*(StartBank+SUM(P$1:P2))*J3/(G3-1),IF(D3="Builder",CapBuilder,CapSingle)*Unit),2))) | O3: =IF(L3="","",IF(M3="Won",L3*G3,IF(M3="Void",L3,IF(M3="Cash out",N(N3),IF(M3="Lost",0,""))))) | P3: =IF(OR(L3="",M3="",M3="Pending"),"",O3-L3) | R3: =IF(OR(G3="",Q3=""),"",G3/Q3-1) | S3: =IF(OR(L3="",J3=""),"",L3*J3) | T3: =IF(P3="","",StartBank+SUM(P$2:P3))
I4: =IF(OR(H4="",H4=0),"",1/H4) | J4: =IF(OR(G4="",H4=""),"",H4*G4-1) | K4: =IF(OR(G4="",H4="",G4<=1),"",IF(J4<IF(D4="Builder",MinEdgeBuilder,IF(D4="Player",MinEdgePlayer,MinEdgeSingle)),0,ROUND(MIN(IF(D4="Single",KellySingle,KellyBuilder)*(StartBank+SUM(P$1:P3))*J4/(G4-1),IF(D4="Builder",CapBuilder,CapSingle)*Unit),2))) | O4: =IF(L4="","",IF(M4="Won",L4*G4,IF(M4="Void",L4,IF(M4="Cash out",N(N4),IF(M4="Lost",0,""))))) | P4: =IF(OR(L4="",M4="",M4="Pending"),"",O4-L4) | R4: =IF(OR(G4="",Q4=""),"",G4/Q4-1) | S4: =IF(OR(L4="",J4=""),"",L4*J4) | T4: =IF(P4="","",StartBank+SUM(P$2:P4))
I5: =IF(OR(H5="",H5=0),"",1/H5) | J5: =IF(OR(G5="",H5=""),"",H5*G5-1) | K5: =IF(OR(G5="",H5="",G5<=1),"",IF(J5<IF(D5="Builder",MinEdgeBuilder,IF(D5="Player",MinEdgePlayer,MinEdgeSingle)),0,ROUND(MIN(IF(D5="Single",KellySingle,KellyBuilder)*(StartBank+SUM(P$1:P4))*J5/(G5-1),IF(D5="Builder",CapBuilder,CapSingle)*Unit),2))) | O5: =IF(L5="","",IF(M5="Won",L5*G5,IF(M5="Void",L5,IF(M5="Cash out",N(N5),IF(M5="Lost",0,""))))) | P5: =IF(OR(L5="",M5="",M5="Pending"),"",O5-L5) | R5: =IF(OR(G5="",Q5=""),"",G5/Q5-1) | S5: =IF(OR(L5="",J5=""),"",L5*J5) | T5: =IF(P5="","",StartBank+SUM(P$2:P5))
I6: =IF(OR(H6="",H6=0),"",1/H6) | J6: =IF(OR(G6="",H6=""),"",H6*G6-1) | K6: =IF(OR(G6="",H6="",G6<=1),"",IF(J6<IF(D6="Builder",MinEdgeBuilder,IF(D6="Player",MinEdgePlayer,MinEdgeSingle)),0,ROUND(MIN(IF(D6="Single",KellySingle,KellyBuilder)*(StartBank+SUM(P$1:P5))*J6/(G6-1),IF(D6="Builder",CapBuilder,CapSingle)*Unit),2))) | O6: =IF(L6="","",IF(M6="Won",L6*G6,IF(M6="Void",L6,IF(M6="Cash out",N(N6),IF(M6="Lost",0,""))))) | P6: =IF(OR(L6="",M6="",M6="Pending"),"",O6-L6) | R6: =IF(OR(G6="",Q6=""),"",G6/Q6-1) | S6: =IF(OR(L6="",J6=""),"",L6*J6) | T6: =IF(P6="","",StartBank+SUM(P$2:P6))
I7: =IF(OR(H7="",H7=0),"",1/H7) | J7: =IF(OR(G7="",H7=""),"",H7*G7-1) | K7: =IF(OR(G7="",H7="",G7<=1),"",IF(J7<IF(D7="Builder",MinEdgeBuilder,IF(D7="Player",MinEdgePlayer,MinEdgeSingle)),0,ROUND(MIN(IF(D7="Single",KellySingle,KellyBuilder)*(StartBank+SUM(P$1:P6))*J7/(G7-1),IF(D7="Builder",CapBuilder,CapSingle)*Unit),2))) | O7: =IF(L7="","",IF(M7="Won",L7*G7,IF(M7="Void",L7,IF(M7="Cash out",N(N7),IF(M7="Lost",0,""))))) | P7: =IF(OR(L7="",M7="",M7="Pending"),"",O7-L7) | R7: =IF(OR(G7="",Q7=""),"",G7/Q7-1) | S7: =IF(OR(L7="",J7=""),"",L7*J7) | T7: =IF(P7="","",StartBank+SUM(P$2:P7))
I8: =IF(OR(H8="",H8=0),"",1/H8) | J8: =IF(OR(G8="",H8=""),"",H8*G8-1) | K8: =IF(OR(G8="",H8="",G8<=1),"",IF(J8<IF(D8="Builder",MinEdgeBuilder,IF(D8="Player",MinEdgePlayer,MinEdgeSingle)),0,ROUND(MIN(IF(D8="Single",KellySingle,KellyBuilder)*(StartBank+SUM(P$1:P7))*J8/(G8-1),IF(D8="Builder",CapBuilder,CapSingle)*Unit),2))) | O8: =IF(L8="","",IF(M8="Won",L8*G8,IF(M8="Void",L8,IF(M8="Cash out",N(N8),IF(M8="Lost",0,""))))) | P8: =IF(OR(L8="",M8="",M8="Pending"),"",O8-L8) | R8: =IF(OR(G8="",Q8=""),"",G8/Q8-1) | S8: =IF(OR(L8="",J8=""),"",L8*J8) | T8: =IF(P8="","",StartBank+SUM(P$2:P8))
I9: =IF(OR(H9="",H9=0),"",1/H9) | J9: =IF(OR(G9="",H9=""),"",H9*G9-1) | K9: =IF(OR(G9="",H9="",G9<=1),"",IF(J9<IF(D9="Builder",MinEdgeBuilder,IF(D9="Player",MinEdgePlayer,MinEdgeSingle)),0,ROUND(MIN(IF(D9="Single",KellySingle,KellyBuilder)*(StartBank+SUM(P$1:P8))*J9/(G9-1),IF(D9="Builder",CapBuilder,CapSingle)*Unit),2))) | O9: =IF(L9="","",IF(M9="Won",L9*G9,IF(M9="Void",L9,IF(M9="Cash out",N(N9),IF(M9="Lost",0,""))))) | P9: =IF(OR(L9="",M9="",M9="Pending"),"",O9-L9) | R9: =IF(OR(G9="",Q9=""),"",G9/Q9-1) | S9: =IF(OR(L9="",J9=""),"",L9*J9) | T9: =IF(P9="","",StartBank+SUM(P$2:P9))
I10: =IF(OR(H10="",H10=0),"",1/H10) | J10: =IF(OR(G10="",H10=""),"",H10*G10-1) | K10: =IF(OR(G10="",H10="",G10<=1),"",IF(J10<IF(D10="Builder",MinEdgeBuilder,IF(D10="Player",MinEdgePlayer,MinEdgeSingle)),0,ROUND(MIN(IF(D10="Single",KellySingle,KellyBuilder)*(StartBank+SUM(P$1:P9))*J10/(G10-1),IF(D10="Builder",CapBuilder,CapSingle)*Unit),2))) | O10: =IF(L10="","",IF(M10="Won",L10*G10,IF(M10="Void",L10,IF(M10="Cash out",N(N10),IF(M10="Lost",0,""))))) | P10: =IF(OR(L10="",M10="",M10="Pending"),"",O10-L10) | R10: =IF(OR(G10="",Q10=""),"",G10/Q10-1) | S10: =IF(OR(L10="",J10=""),"",L10*J10) | T10: =IF(P10="","",StartBank+SUM(P$2:P10))
I11: =IF(OR(H11="",H11=0),"",1/H11) | J11: =IF(OR(G11="",H11=""),"",H11*G11-1) | K11: =IF(OR(G11="",H11="",G11<=1),"",IF(J11<IF(D11="Builder",MinEdgeBuilder,IF(D11="Player",MinEdgePlayer,MinEdgeSingle)),0,ROUND(MIN(IF(D11="Single",KellySingle,KellyBuilder)*(StartBank+SUM(P$1:P10))*J11/(G11-1),IF(D11="Builder",CapBuilder,CapSingle)*Unit),2))) | O11: =IF(L11="","",IF(M11="Won",L11*G11,IF(M11="Void",L11,IF(M11="Cash out",N(N11),IF(M11="Lost",0,""))))) | P11: =IF(OR(L11="",M11="",M11="Pending"),"",O11-L11) | R11: =IF(OR(G11="",Q11=""),"",G11/Q11-1) | S11: =IF(OR(L11="",J11=""),"",L11*J11) | T11: =IF(P11="","",StartBank+SUM(P$2:P11))
I12: =IF(OR(H12="",H12=0),"",1/H12) | J12: =IF(OR(G12="",H12=""),"",H12*G12-1) | K12: =IF(OR(G12="",H12="",G12<=1),"",IF(J12<IF(D12="Builder",MinEdgeBuilder,IF(D12="Player",MinEdgePlayer,MinEdgeSingle)),0,ROUND(MIN(IF(D12="Single",KellySingle,KellyBuilder)*(StartBank+SUM(P$1:P11))*J12/(G12-1),IF(D12="Builder",CapBuilder,CapSingle)*Unit),2))) | O12: =IF(L12="","",IF(M12="Won",L12*G12,IF(M12="Void",L12,IF(M12="Cash out",N(N12),IF(M12="Lost",0,""))))) | P12: =IF(OR(L12="",M12="",M12="Pending"),"",O12-L12) | R12: =IF(OR(G12="",Q12=""),"",G12/Q12-1) | S12: =IF(OR(L12="",J12=""),"",L12*J12) | T12: =IF(P12="","",StartBank+SUM(P$2:P12))
I13: =IF(OR(H13="",H13=0),"",1/H13) | J13: =IF(OR(G13="",H13=""),"",H13*G13-1) | K13: =IF(OR(G13="",H13="",G13<=1),"",IF(J13<IF(D13="Builder",MinEdgeBuilder,IF(D13="Player",MinEdgePlayer,MinEdgeSingle)),0,ROUND(MIN(IF(D13="Single",KellySingle,KellyBuilder)*(StartBank+SUM(P$1:P12))*J13/(G13-1),IF(D13="Builder",CapBuilder,CapSingle)*Unit),2))) | O13: =IF(L13="","",IF(M13="Won",L13*G13,IF(M13="Void",L13,IF(M13="Cash out",N(N13),IF(M13="Lost",0,""))))) | P13: =IF(OR(L13="",M13="",M13="Pending"),"",O13-L13) | R13: =IF(OR(G13="",Q13=""),"",G13/Q13-1) | S13: =IF(OR(L13="",J13=""),"",L13*J13) | T13: =IF(P13="","",StartBank+SUM(P$2:P13))
... I2001: =IF(OR(H2001="",H2001=0),"",1/H2001) | J2001: =IF(OR(G2001="",H2001=""),"",H2001*G2001-1) | K2001: =IF(OR(G2001="",H2001="",G2001<=1),"",IF(J2001<IF(D2001="Builder",MinEdgeBuilder,IF(D2001="Player",MinEdgePlayer,MinEdgeSingle)),0,ROUND(MIN(IF(D2001="Single",KellySingle,KellyBuilder)*(StartBank+SUM(P$1:P2000))*J2001/(G2001-1),IF(D2001="Builder",CapBuilder,CapSingle)*Unit),2))) | O2001: =IF(L2001="","",IF(M2001="Won",L2001*G2001,IF(M2001="Void",L2001,IF(M2001="Cash out",N(N2001),IF(M2001="Lost",0,""))))) | P2001: =IF(OR(L2001="",M2001="",M2001="Pending"),"",O2001-L2001) | R2001: =IF(OR(G2001="",Q2001=""),"",G2001/Q2001-1) | S2001: =IF(OR(L2001="",J2001=""),"",L2001*J2001) | T2001: =IF(P2001="","",StartBank+SUM(P$2:P2001))

Sheet How to use
A1: How to use this tracker
A3: 1. Settings: enter your starting bank (money set aside for betting only). Leave the rest unless you want to change the plan.
A4: 2. Bets: add one row per bet before the match. Fill in the yellow cells: date, match, bookmaker, type (Single, Player or Builder),
A5: market, what you backed, the odds you took, the model's chance (from the match report) and your stake.
A6: 'Suggested stake' shows what the staking plan recommends. 0 means the edge is too small: skip the bet.
A7: 3. After the match set Result to Won, Lost, Void or Cash out (and enter the cash-out amount).
A8: 4. Optional but valuable: enter the closing odds (the price just before kick-off) so the sheet can work out CLV.
A9: 5. Summary updates itself: profit, ROI, strike rate, model-expected profit versus actual, and results by month,
A10: bet type and market.
A12: Reading the numbers
A13: - ROI = profit ÷ total staked. Bookmaker margins mean the average bettor's ROI is negative; anything above 0% over
A14: several hundred bets is good. Over 50 bets, luck dominates: do not judge the model on a handful of results.
... A19: You can also just tell Claude in the project what you backed and the result, and it will fill the sheet in for you.
